Workbook

Sheet Generator
A1: 🍽 Weekly Meal Generator — by cuisine
A2: Type how many of each cuisine you want per meal. Each row can total anything (e.g. 7).
B4: Asian | C4: Chinese | D4: Western | E4: Total
A5: Breakfast | B5: 2 | C5: 2 | D5: 3 | E5: =SUM(B5:D5)
A6: Lunch | B6: 3 | C6: 2 | D6: 2 | E6: =SUM(B6:D6)
A7: Dinner | B7: 2 | C7: 3 | D7: 2 | E7: =SUM(B7:D7)
A8: Max available → | B8: B 3 / L 26 / D 89 | C8: B 2 / L 26 / D160 | D8: B 11 / L 44 / D 58
A9: ↻ Reshuffle: | B9: tap a cell, type a space, Enter, delete — refreshes all picks.
A11: 🥐 BREAKFAST
A12: # | B12: Cuisine | C12: Recipe | D12: Ingredients | E12: Recipe link
A13: =IF($F13=0,"",1) | B13: =IF($F13=0,"",IF($F13=1,"Asian",IF($F13=2,"Chinese","Western"))) | C13: {=IFERROR(IF($F13=1,INDEX('All Recipes'!$A$2:$A$554,MATCH(LARGE('All Recipes'!$G$2:$G$554,$G13),'All Recipes'!$G$2:$G$554,0)),IF($F13=2,INDEX('All Recipes'!$A$2:$A$554,MATCH(LARGE('All Recipes'!$H$2:$H$554,$G13),'All Recipes'!$H$2:$H$554,0)),IF($F13=3,INDEX('All Recipes'!$A$2:$A$554,MATCH(LARGE('All Recipes'!$I$2:$I$554,$G13),'All Recipes'!$I$2:$I$554,0)),""))),"")} | D13: {=IFERROR(IF($F13=1,INDEX('All Recipes'!$B$2:$B$554,MATCH(LARGE('All Recipes'!$G$2:$G$554,$G13),'All Recipes'!$G$2:$G$554,0)),IF($F13=2,INDEX('All Recipes'!$B$2:$B$554,MATCH(LARGE('All Recipes'!$H$2:$H$554,$G13),'All Recipes'!$H$2:$H$554,0)),IF($F13=3,INDEX('All Recipes'!$B$2:$B$554,MATCH(LARGE('All Recipes'!$I$2:$I$554,$G13),'All Recipes'!$I$2:$I$554,0)),""))),"")} | E13: {=IFERROR(IF($F13=1,INDEX('All Recipes'!$F$2:$F$554,MATCH(LARGE('All Recipes'!$G$2:$G$554,$G13),'All Recipes'!$G$2:$G$554,0)),IF($F13=2,INDEX('All Recipes'!$F$2:$F$554,MATCH(LARGE('All Recipes'!$H$2:$H$554,$G13),'All Recipes'!$H$2:$H$554,0)),IF($F13=3,INDEX('All Recipes'!$F$2:$F$554,MATCH(LARGE('All Recipes'!$I$2:$I$554,$G13),'All Recipes'!$I$2:$I$554,0)),""))),"")} | F13: =IF(1<=$B$5,1,IF(1<=$B$5+$C$5,2,IF(1<=$B$5+$C$5+$D$5,3,0))) | G13: =IF(1<=$B$5,1,IF(1<=$B$5+$C$5,1-$B$5,IF(1<=$B$5+$C$5+$D$5,1-$B$5-$C$5,0)))
A14: =IF($F14=0,"",2) | B14: =IF($F14=0,"",IF($F14=1,"Asian",IF($F14=2,"Chinese","Western"))) | C14: {=IFERROR(IF($F14=1,INDEX('All Recipes'!$A$2:$A$554,MATCH(LARGE('All Recipes'!$G$2:$G$554,$G14),'All Recipes'!$G$2:$G$554,0)),IF($F14=2,INDEX('All Recipes'!$A$2:$A$554,MATCH(LARGE('All Recipes'!$H$2:$H$554,$G14),'All Recipes'!$H$2:$H$554,0)),IF($F14=3,INDEX('All Recipes'!$A$2:$A$554,MATCH(LARGE('All Recipes'!$I$2:$I$554,$G14),'All Recipes'!$I$2:$I$554,0)),""))),"")} | D14: {=IFERROR(IF($F14=1,INDEX('All Recipes'!$B$2:$B$554,MATCH(LARGE('All Recipes'!$G$2:$G$554,$G14),'All Recipes'!$G$2:$G$554,0)),IF($F14=2,INDEX('All Recipes'!$B$2:$B$554,MATCH(LARGE('All Recipes'!$H$2:$H$554,$G14),'All Recipes'!$H$2:$H$554,0)),IF($F14=3,INDEX('All Recipes'!$B$2:$B$554,MATCH(LARGE('All Recipes'!$I$2:$I$554,$G14),'All Recipes'!$I$2:$I$554,0)),""))),"")} | E14: {=IFERROR(IF($F14=1,INDEX('All Recipes'!$F$2:$F$554,MATCH(LARGE('All Recipes'!$G$2:$G$554,$G14),'All Recipes'!$G$2:$G$554,0)),IF($F14=2,INDEX('All Recipes'!$F$2:$F$554,MATCH(LARGE('All Recipes'!$H$2:$H$554,$G14),'All Recipes'!$H$2:$H$554,0)),IF($F14=3,INDEX('All Recipes'!$F$2:$F$554,MATCH(LARGE('All Recipes'!$I$2:$I$554,$G14),'All Recipes'!$I$2:$I$554,0)),""))),"")} | F14: =IF(2<=$B$5,1,IF(2<=$B$5+$C$5,2,IF(2<=$B$5+$C$5+$D$5,3,0))) | G14: =IF(2<=$B$5,2,IF(2<=$B$5+$C$5,2-$B$5,IF(2<=$B$5+$C$5+$D$5,2-$B$5-$C$5,0)))
A15: =IF($F15=0,"",3) | B15: =IF($F15=0,"",IF($F15=1,"Asian",IF($F15=2,"Chinese","Western"))) | C15: {=IFERROR(IF($F15=1,INDEX('All Recipes'!$A$2:$A$554,MATCH(LARGE('All Recipes'!$G$2:$G$554,$G15),'All Recipes'!$G$2:$G$554,0)),IF($F15=2,INDEX('All Recipes'!$A$2:$A$554,MATCH(LARGE('All Recipes'!$H$2:$H$554,$G15),'All Recipes'!$H$2:$H$554,0)),IF($F15=3,INDEX('All Recipes'!$A$2:$A$554,MATCH(LARGE('All Recipes'!$I$2:$I$554,$G15),'All Recipes'!$I$2:$I$554,0)),""))),"")} | D15: {=IFERROR(IF($F15=1,INDEX('All Recipes'!$B$2:$B$554,MATCH(LARGE('All Recipes'!$G$2:$G$554,$G15),'All Recipes'!$G$2:$G$554,0)),IF($F15=2,INDEX('All Recipes'!$B$2:$B$554,MATCH(LARGE('All Recipes'!$H$2:$H$554,$G15),'All Recipes'!$H$2:$H$554,0)),IF($F15=3,INDEX('All Recipes'!$B$2:$B$554,MATCH(LARGE('All Recipes'!$I$2:$I$554,$G15),'All Recipes'!$I$2:$I$554,0)),""))),"")} | E15: {=IFERROR(IF($F15=1,INDEX('All Recipes'!$F$2:$F$554,MATCH(LARGE('All Recipes'!$G$2:$G$554,$G15),'All Recipes'!$G$2:$G$554,0)),IF($F15=2,INDEX('All Recipes'!$F$2:$F$554,MATCH(LARGE('All Recipes'!$H$2:$H$554,$G15),'All Recipes'!$H$2:$H$554,0)),IF($F15=3,INDEX('All Recipes'!$F$2:$F$554,MATCH(LARGE('All Recipes'!$I$2:$I$554,$G15),'All Recipes'!$I$2:$I$554,0)),""))),"")} | F15: =IF(3<=$B$5,1,IF(3<=$B$5+$C$5,2,IF(3<=$B$5+$C$5+$D$5,3,0))) | G15: =IF(3<=$B$5,3,IF(3<=$B$5+$C$5,3-$B$5,IF(3<=$B$5+$C$5+$D$5,3-$B$5-$C$5,0)))
A16: =IF($F16=0,"",4) | B16: =IF($F16=0,"",IF($F16=1,"Asian",IF($F16=2,"Chinese","Western"))) | C16: {=IFERROR(IF($F16=1,INDEX('All Recipes'!$A$2:$A$554,MATCH(LARGE('All Recipes'!$G$2:$G$554,$G16),'All Recipes'!$G$2:$G$554,0)),IF($F16=2,INDEX('All Recipes'!$A$2:$A$554,MATCH(LARGE('All Recipes'!$H$2:$H$554,$G16),'All Recipes'!$H$2:$H$554,0)),IF($F16=3,INDEX('All Recipes'!$A$2:$A$554,MATCH(LARGE('All Recipes'!$I$2:$I$554,$G16),'All Recipes'!$I$2:$I$554,0)),""))),"")} | D16: {=IFERROR(IF($F16=1,INDEX('All Recipes'!$B$2:$B$554,MATCH(LARGE('All Recipes'!$G$2:$G$554,$G16),'All Recipes'!$G$2:$G$554,0)),IF($F16=2,INDEX('All Recipes'!$B$2:$B$554,MATCH(LARGE('All Recipes'!$H$2:$H$554,$G16),'All Recipes'!$H$2:$H$554,0)),IF($F16=3,INDEX('All Recipes'!$B$2:$B$554,MATCH(LARGE('All Recipes'!$I$2:$I$554,$G16),'All Recipes'!$I$2:$I$554,0)),""))),"")} | E16: {=IFERROR(IF($F16=1,INDEX('All Recipes'!$F$2:$F$554,MATCH(LARGE('All Recipes'!$G$2:$G$554,$G16),'All Recipes'!$G$2:$G$554,0)),IF($F16=2,INDEX('All Recipes'!$F$2:$F$554,MATCH(LARGE('All Recipes'!$H$2:$H$554,$G16),'All Recipes'!$H$2:$H$554,0)),IF($F16=3,INDEX('All Recipes'!$F$2:$F$554,MATCH(LARGE('All Recipes'!$I$2:$I$554,$G16),'All Recipes'!$I$2:$I$554,0)),""))),"")} | F16: =IF(4<=$B$5,1,IF(4<=$B$5+$C$5,2,IF(4<=$B$5+$C$5+$D$5,3,0))) | G16: =IF(4<=$B$5,4,IF(4<=$B$5+$C$5,4-$B$5,IF(4<=$B$5+$C$5+$D$5,4-$B$5-$C$5,0)))
A17: =IF($F17=0,"",5) | B17: =IF($F17=0,"",IF($F17=1,"Asian",IF($F17=2,"Chinese","Western"))) | C17: {=IFERROR(IF($F17=1,INDEX('All Recipes'!$A$2:$A$554,MATCH(LARGE('All Recipes'!$G$2:$G$554,$G17),'All Recipes'!$G$2:$G$554,0)),IF($F17=2,INDEX('All Recipes'!$A$2:$A$554,MATCH(LARGE('All Recipes'!$H$2:$H$554,$G17),'All Recipes'!$H$2:$H$554,0)),IF($F17=3,INDEX('All Recipes'!$A$2:$A$554,MATCH(LARGE('All Recipes'!$I$2:$I$554,$G17),'All Recipes'!$I$2:$I$554,0)),""))),"")} | D17: {=IFERROR(IF($F17=1,INDEX('All Recipes'!$B$2:$B$554,MATCH(LARGE('All Recipes'!$G$2:$G$554,$G17),'All Recipes'!$G$2:$G$554,0)),IF($F17=2,INDEX('All Recipes'!$B$2:$B$554,MATCH(LARGE('All Recipes'!$H$2:$H$554,$G17),'All Recipes'!$H$2:$H$554,0)),IF($F17=3,INDEX('All Recipes'!$B$2:$B$554,MATCH(LARGE('All Recipes'!$I$2:$I$554,$G17),'All Recipes'!$I$2:$I$554,0)),""))),"")} | E17: {=IFERROR(IF($F17=1,INDEX('All Recipes'!$F$2:$F$554,MATCH(LARGE('All Recipes'!$G$2:$G$554,$G17),'All Recipes'!$G$2:$G$554,0)),IF($F17=2,INDEX('All Recipes'!$F$2:$F$554,MATCH(LARGE('All Recipes'!$H$2:$H$554,$G17),'All Recipes'!$H$2:$H$554,0)),IF($F17=3,INDEX('All Recipes'!$F$2:$F$554,MATCH(LARGE('All Recipes'!$I$2:$I$554,$G17),'All Recipes'!$I$2:$I$554,0)),""))),"")} | F17: =IF(5<=$B$5,1,IF(5<=$B$5+$C$5,2,IF(5<=$B$5+$C$5+$D$5,3,0))) | G17: =IF(5<=$B$5,5,IF(5<=$B$5+$C$5,5-$B$5,IF(5<=$B$5+$C$5+$D$5,5-$B$5-$C$5,0)))
A18: =IF($F18=0,"",6) | B18: =IF($F18=0,"",IF($F18=1,"Asian",IF($F18=2,"Chinese","Western"))) | C18: {=IFERROR(IF($F18=1,INDEX('All Recipes'!$A$2:$A$554,MATCH(LARGE('All Recipes'!$G$2:$G$554,$G18),'All Recipes'!$G$2:$G$554,0)),IF($F18=2,INDEX('All Recipes'!$A$2:$A$554,MATCH(LARGE('All Recipes'!$H$2:$H$554,$G18),'All Recipes'!$H$2:$H$554,0)),IF($F18=3,INDEX('All Recipes'!$A$2:$A$554,MATCH(LARGE('All Recipes'!$I$2:$I$554,$G18),'All Recipes'!$I$2:$I$554,0)),""))),"")} | D18: {=IFERROR(IF($F18=1,INDEX('All Recipes'!$B$2:$B$554,MATCH(LARGE('All Recipes'!$G$2:$G$554,$G18),'All Recipes'!$G$2:$G$554,0)),IF($F18=2,INDEX('All Recipes'!$B$2:$B$554,MATCH(LARGE('All Recipes'!$H$2:$H$554,$G18),'All Recipes'!$H$2:$H$554,0)),IF($F18=3,INDEX('All Recipes'!$B$2:$B$554,MATCH(LARGE('All Recipes'!$I$2:$I$554,$G18),'All Recipes'!$I$2:$I$554,0)),""))),"")} | E18: {=IFERROR(IF($F18=1,INDEX('All Recipes'!$F$2:$F$554,MATCH(LARGE('All Recipes'!$G$2:$G$554,$G18),'All Recipes'!$G$2:$G$554,0)),IF($F18=2,INDEX('All Recipes'!$F$2:$F$554,MATCH(LARGE('All Recipes'!$H$2:$H$554,$G18),'All Recipes'!$H$2:$H$554,0)),IF($F18=3,INDEX('All Recipes'!$F$2:$F$554,MATCH(LARGE('All Recipes'!$I$2:$I$554,$G18),'All Recipes'!$I$2:$I$554,0)),""))),"")} | F18: =IF(6<=$B$5,1,IF(6<=$B$5+$C$5,2,IF(6<=$B$5+$C$5+$D$5,3,0))) | G18: =IF(6<=$B$5,6,IF(6<=$B$5+$C$5,6-$B$5,IF(6<=$B$5+$C$5+$D$5,6-$B$5-$C$5,0)))
A19: =IF($F19=0,"",7) | B19: =IF($F19=0,"",IF($F19=1,"Asian",IF($F19=2,"Chinese","Western"))) | C19: {=IFERROR(IF($F19=1,INDEX('All Recipes'!$A$2:$A$554,MATCH(LARGE('All Recipes'!$G$2:$G$554,$G19),'All Recipes'!$G$2:$G$554,0)),IF($F19=2,INDEX('All Recipes'!$A$2:$A$554,MATCH(LARGE('All Recipes'!$H$2:$H$554,$G19),'All Recipes'!$H$2:$H$554,0)),IF($F19=3,INDEX('All Recipes'!$A$2:$A$554,MATCH(LARGE('All Recipes'!$I$2:$I$554,$G19),'All Recipes'!$I$2:$I$554,0)),""))),"")} | D19: {=IFERROR(IF($F19=1,INDEX('All Recipes'!$B$2:$B$554,MATCH(LARGE('All Recipes'!$G$2:$G$554,$G19),'All Recipes'!$G$2:$G$554,0)),IF($F19=2,INDEX('All Recipes'!$B$2:$B$554,MATCH(LARGE('All Recipes'!$H$2:$H$554,$G19),'All Recipes'!$H$2:$H$554,0)),IF($F19=3,INDEX('All Recipes'!$B$2:$B$554,MATCH(LARGE('All Recipes'!$I$2:$I$554,$G19),'All Recipes'!$I$2:$I$554,0)),""))),"")} | E19: {=IFERROR(IF($F19=1,INDEX('All Recipes'!$F$2:$F$554,MATCH(LARGE('All Recipes'!$G$2:$G$554,$G19),'All Recipes'!$G$2:$G$554,0)),IF($F19=2,INDEX('All Recipes'!$F$2:$F$554,MATCH(LARGE('All Recipes'!$H$2:$H$554,$G19),'All Recipes'!$H$2:$H$554,0)),IF($F19=3,INDEX('All Recipes'!$F$2:$F$554,MATCH(LARGE('All Recipes'!$I$2:$I$554,$G19),'All Recipes'!$I$2:$I$554,0)),""))),"")} | F19: =IF(7<=$B$5,1,IF(7<=$B$5+$C$5,2,IF(7<=$B$5+$C$5+$D$5,3,0))) | G19: =IF(7<=$B$5,7,IF(7<=$B$5+$C$5,7-$B$5,IF(7<=$B$5+$C$5+$D$5,7-$B$5-$C$5,0)))
A20: =IF($F20=0,"",8) | B20: =IF($F20=0,"",IF($F20=1,"Asian",IF($F20=2,"Chinese","Western"))) | C20: {=IFERROR(IF($F20=1,INDEX('All Recipes'!$A$2:$A$554,MATCH(LARGE('All Recipes'!$G$2:$G$554,$G20),'All Recipes'!$G$2:$G$554,0)),IF($F20=2,INDEX('All Recipes'!$A$2:$A$554,MATCH(LARGE('All Recipes'!$H$2:$H$554,$G20),'All Recipes'!$H$2:$H$554,0)),IF($F20=3,INDEX('All Recipes'!$A$2:$A$554,MATCH(LARGE('All Recipes'!$I$2:$I$554,$G20),'All Recipes'!$I$2:$I$554,0)),""))),"")} | D20: {=IFERROR(IF($F20=1,INDEX('All Recipes'!$B$2:$B$554,MATCH(LARGE('All Recipes'!$G$2:$G$554,$G20),'All Recipes'!$G$2:$G$554,0)),IF($F20=2,INDEX('All Recipes'!$B$2:$B$554,MATCH(LARGE('All Recipes'!$H$2:$H$554,$G20),'All Recipes'!$H$2:$H$554,0)),IF($F20=3,INDEX('All Recipes'!$B$2:$B$554,MATCH(LARGE('All Recipes'!$I$2:$I$554,$G20),'All Recipes'!$I$2:$I$554,0)),""))),"")} | E20: {=IFERROR(IF($F20=1,INDEX('All Recipes'!$F$2:$F$554,MATCH(LARGE('All Recipes'!$G$2:$G$554,$G20),'All Recipes'!$G$2:$G$554,0)),IF($F20=2,INDEX('All Recipes'!$F$2:$F$554,MATCH(LARGE('All Recipes'!$H$2:$H$554,$G20),'All Recipes'!$H$2:$H$554,0)),IF($F20=3,INDEX('All Recipes'!$F$2:$F$554,MATCH(LARGE('All Recipes'!$I$2:$I$554,$G20),'All Recipes'!$I$2:$I$554,0)),""))),"")} | F20: =IF(8<=$B$5,1,IF(8<=$B$5+$C$5,2,IF(8<=$B$5+$C$5+$D$5,3,0))) | G20: =IF(8<=$B$5,8,IF(8<=$B$5+$C$5,8-$B$5,IF(8<=$B$5+$C$5+$D$5,8-$B$5-$C$5,0)))
A21: =IF($F21=0,"",9) | B21: =IF($F21=0,"",IF($F21=1,"Asian",IF($F21=2,"Chinese","Western"))) | C21: {=IFERROR(IF($F21=1,INDEX('All Recipes'!$A$2:$A$554,MATCH(LARGE('All Recipes'!$G$2:$G$554,$G21),'All Recipes'!$G$2:$G$554,0)),IF($F21=2,INDEX('All Recipes'!$A$2:$A$554,MATCH(LARGE('All Recipes'!$H$2:$H$554,$G21),'All Recipes'!$H$2:$H$554,0)),IF($F21=3,INDEX('All Recipes'!$A$2:$A$554,MATCH(LARGE('All Recipes'!$I$2:$I$554,$G21),'All Recipes'!$I$2:$I$554,0)),""))),"")} | D21: {=IFERROR(IF($F21=1,INDEX('All Recipes'!$B$2:$B$554,MATCH(LARGE('All Recipes'!$G$2:$G$554,$G21),'All Recipes'!$G$2:$G$554,0)),IF($F21=2,INDEX('All Recipes'!$B$2:$B$554,MATCH(LARGE('All Recipes'!$H$2:$H$554,$G21),'All Recipes'!$H$2:$H$554,0)),IF($F21=3,INDEX('All Recipes'!$B$2:$B$554,MATCH(LARGE('All Recipes'!$I$2:$I$554,$G21),'All Recipes'!$I$2:$I$554,0)),""))),"")} | E21: {=IFERROR(IF($F21=1,INDEX('All Recipes'!$F$2:$F$554,MATCH(LARGE('All Recipes'!$G$2:$G$554,$G21),'All Recipes'!$G$2:$G$554,0)),IF($F21=2,INDEX('All Recipes'!$F$2:$F$554,MATCH(LARGE('All Recipes'!$H$2:$H$554,$G21),'All Recipes'!$H$2:$H$554,0)),IF($F21=3,INDEX('All Recipes'!$F$2:$F$554,MATCH(LARGE('All Recipes'!$I$2:$I$554,$G21),'All Recipes'!$I$2:$I$554,0)),""))),"")} | F21: =IF(9<=$B$5,1,IF(9<=$B$5+$C$5,2,IF(9<=$B$5+$C$5+$D$5,3,0))) | G21: =IF(9<=$B$5,9,IF(9<=$B$5+$C$5,9-$B$5,IF(9<=$B$5+$C$5+$D$5,9-$B$5-$C$5,0)))
A22: =IF($F22=0,"",10) | B22: =IF($F22=0,"",IF($F22=1,"Asian",IF($F22=2,"Chinese","Western"))) | C22: {=IFERROR(IF($F22=1,INDEX('All Recipes'!$A$2:$A$554,MATCH(LARGE('All Recipes'!$G$2:$G$554,$G22),'All Recipes'!$G$2:$G$554,0)),IF($F22=2,INDEX('All Recipes'!$A$2:$A$554,MATCH(LARGE('All Recipes'!$H$2:$H$554,$G22),'All Recipes'!$H$2:$H$554,0)),IF($F22=3,INDEX('All Recipes'!$A$2:$A$554,MATCH(LARGE('All Recipes'!$I$2:$I$554,$G22),'All Recipes'!$I$2:$I$554,0)),""))),"")} | D22: {=IFERROR(IF($F22=1,INDEX('All Recipes'!$B$2:$B$554,MATCH(LARGE('All Recipes'!$G$2:$G$554,$G22),'All Recipes'!$G$2:$G$554,0)),IF($F22=2,INDEX('All Recipes'!$B$2:$B$554,MATCH(LARGE('All Recipes'!$H$2:$H$554,$G22),'All Recipes'!$H$2:$H$554,0)),IF($F22=3,INDEX('All Recipes'!$B$2:$B$554,MATCH(LARGE('All Recipes'!$I$2:$I$554,$G22),'All Recipes'!$I$2:$I$554,0)),""))),"")} | E22: {=IFERROR(IF($F22=1,INDEX('All Recipes'!$F$2:$F$554,MATCH(LARGE('All Recipes'!$G$2:$G$554,$G22),'All Recipes'!$G$2:$G$554,0)),IF($F22=2,INDEX('All Recipes'!$F$2:$F$554,MATCH(LARGE('All Recipes'!$H$2:$H$554,$G22),'All Recipes'!$H$2:$H$554,0)),IF($F22=3,INDEX('All Recipes'!$F$2:$F$554,MATCH(LARGE('All Recipes'!$I$2:$I$554,$G22),'All Recipes'!$I$2:$I$554,0)),""))),"")} | F22: =IF(10<=$B$5,1,IF(10<=$B$5+$C$5,2,IF(10<=$B$5+$C$5+$D$5,3,0))) | G22: =IF(10<=$B$5,10,IF(10<=$B$5+$C$5,10-$B$5,IF(10<=$B$5+$C$5+$D$5,10-$B$5-$C$5,0)))
A23: =IF($F23=0,"",11) | B23: =IF($F23=0,"",IF($F23=1,"Asian",IF($F23=2,"Chinese","Western"))) | C23: {=IFERROR(IF($F23=1,INDEX('All Recipes'!$A$2:$A$554,MATCH(LARGE('All Recipes'!$G$2:$G$554,$G23),'All Recipes'!$G$2:$G$554,0)),IF($F23=2,INDEX('All Recipes'!$A$2:$A$554,MATCH(LARGE('All Recipes'!$H$2:$H$554,$G23),'All Recipes'!$H$2:$H$554,0)),IF($F23=3,INDEX('All Recipes'!$A$2:$A$554,MATCH(LARGE('All Recipes'!$I$2:$I$554,$G23),'All Recipes'!$I$2:$I$554,0)),""))),"")} | D23: {=IFERROR(IF($F23=1,INDEX('All Recipes'!$B$2:$B$554,MATCH(LARGE('All Recipes'!$G$2:$G$554,$G23),'All Recipes'!$G$2:$G$554,0)),IF($F23=2,INDEX('All Recipes'!$B$2:$B$554,MATCH(LARGE('All Recipes'!$H$2:$H$554,$G23),'All Recipes'!$H$2:$H$554,0)),IF($F23=3,INDEX('All Recipes'!$B$2:$B$554,MATCH(LARGE('All Recipes'!$I$2:$I$554,$G23),'All Recipes'!$I$2:$I$554,0)),""))),"")} | E23: {=IFERROR(IF($F23=1,INDEX('All Recipes'!$F$2:$F$554,MATCH(LARGE('All Recipes'!$G$2:$G$554,$G23),'All Recipes'!$G$2:$G$554,0)),IF($F23=2,INDEX('All Recipes'!$F$2:$F$554,MATCH(LARGE('All Recipes'!$H$2:$H$554,$G23),'All Recipes'!$H$2:$H$554,0)),IF($F23=3,INDEX('All Recipes'!$F$2:$F$554,MATCH(LARGE('All Recipes'!$I$2:$I$554,$G23),'All Recipes'!$I$2:$I$554,0)),""))),"")} | F23: =IF(11<=$B$5,1,IF(11<=$B$5+$C$5,2,IF(11<=$B$5+$C$5+$D$5,3,0))) | G23: =IF(11<=$B$5,11,IF(11<=$B$5+$C$5,11-$B$5,IF(11<=$B$5+$C$5+$D$5,11-$B$5-$C$5,0)))
A24: =IF($F24=0,"",12) | B24: =IF($F24=0,"",IF($F24=1,"Asian",IF($F24=2,"Chinese","Western"))) | C24: {=IFERROR(IF($F24=1,INDEX('All Recipes'!$A$2:$A$554,MATCH(LARGE('All Recipes'!$G$2:$G$554,$G24),'All Recipes'!$G$2:$G$554,0)),IF($F24=2,INDEX('All Recipes'!$A$2:$A$554,MATCH(LARGE('All Recipes'!$H$2:$H$554,$G24),'All Recipes'!$H$2:$H$554,0)),IF($F24=3,INDEX('All Recipes'!$A$2:$A$554,MATCH(LARGE('All Recipes'!$I$2:$I$554,$G24),'All Recipes'!$I$2:$I$554,0)),""))),"")} | D24: {=IFERROR(IF($F24=1,INDEX('All Recipes'!$B$2:$B$554,MATCH(LARGE('All Recipes'!$G$2:$G$554,$G24),'All Recipes'!$G$2:$G$554,0)),IF($F24=2,INDEX('All Recipes'!$B$2:$B$554,MATCH(LARGE('All Recipes'!$H$2:$H$554,$G24),'All Recipes'!$H$2:$H$554,0)),IF($F24=3,INDEX('All Recipes'!$B$2:$B$554,MATCH(LARGE('All Recipes'!$I$2:$I$554,$G24),'All Recipes'!$I$2:$I$554,0)),""))),"")} | E24: {=IFERROR(IF($F24=1,INDEX('All Recipes'!$F$2:$F$554,MATCH(LARGE('All Recipes'!$G$2:$G$554,$G24),'All Recipes'!$G$2:$G$554,0)),IF($F24=2,INDEX('All Recipes'!$F$2:$F$554,MATCH(LARGE('All Recipes'!$H$2:$H$554,$G24),'All Recipes'!$H$2:$H$554,0)),IF($F24=3,INDEX('All Recipes'!$F$2:$F$554,MATCH(LARGE('All Recipes'!$I$2:$I$554,$G24),'All Recipes'!$I$2:$I$554,0)),""))),"")} | F24: =IF(12<=$B$5,1,IF(12<=$B$5+$C$5,2,IF(12<=$B$5+$C$5+$D$5,3,0))) | G24: =IF(12<=$B$5,12,IF(12<=$B$5+$C$5,12-$B$5,IF(12<=$B$5+$C$5+$D$5,12-$B$5-$C$5,0)))
A26: 🥗 LUNCH
A27: # | B27: Cuisine | C27: Recipe | D27: Ingredients | E27: Recipe link
A28: =IF($F28=0,"",1) | B28: =IF($F28=0,"",IF($F28=1,"Asian",IF($F28=2,"Chinese","Western"))) | C28: {=IFERROR(IF($F28=1,INDEX('All Recipes'!$A$2:$A$554,MATCH(LARGE('All Recipes'!$J$2:$J$554,$G28),'All Recipes'!$J$2:$J$554,0)),IF($F28=2,INDEX('All Recipes'!$A$2:$A$554,MATCH(LARGE('All Recipes'!$K$2:$K$554,$G28),'All Recipes'!$K$2:$K$554,0)),IF($F28=3,INDEX('All Recipes'!$A$2:$A$554,MATCH(LARGE('All Recipes'!$L$2:$L$554,$G28),'All Recipes'!$L$2:$L$554,0)),""))),"")} | D28: {=IFERROR(IF($F28=1,INDEX('All Recipes'!$B$2:$B$554,MATCH(LARGE('All Recipes'!$J$2:$J$554,$G28),'All Recipes'!$J$2:$J$554,0)),IF($F28=2,INDEX('All Recipes'!$B$2:$B$554,MATCH(LARGE('All Recipes'!$K$2:$K$554,$G28),'All Recipes'!$K$2:$K$554,0)),IF($F28=3,INDEX('All Recipes'!$B$2:$B$554,MATCH(LARGE('All Recipes'!$L$2:$L$554,$G28),'All Recipes'!$L$2:$L$554,0)),""))),"")} | E28: {=IFERROR(IF($F28=1,INDEX('All Recipes'!$F$2:$F$554,MATCH(LARGE('All Recipes'!$J$2:$J$554,$G28),'All Recipes'!$J$2:$J$554,0)),IF($F28=2,INDEX('All Recipes'!$F$2:$F$554,MATCH(LARGE('All Recipes'!$K$2:$K$554,$G28),'All Recipes'!$K$2:$K$554,0)),IF($F28=3,INDEX('All Recipes'!$F$2:$F$554,MATCH(LARGE('All Recipes'!$L$2:$L$554,$G28),'All Recipes'!$L$2:$L$554,0)),""))),"")} | F28: =IF(1<=$B$6,1,IF(1<=$B$6+$C$6,2,IF(1<=$B$6+$C$6+$D$6,3,0))) | G28: =IF(1<=$B$6,1,IF(1<=$B$6+$C$6,1-$B$6,IF(1<=$B$6+$C$6+$D$6,1-$B$6-$C$6,0)))
A29: =IF($F29=0,"",2) | B29: =IF($F29=0,"",IF($F29=1,"Asian",IF($F29=2,"Chinese","Western"))) | C29: {=IFERROR(IF($F29=1,INDEX('All Recipes'!$A$2:$A$554,MATCH(LARGE('All Recipes'!$J$2:$J$554,$G29),'All Recipes'!$J$2:$J$554,0)),IF($F29=2,INDEX('All Recipes'!$A$2:$A$554,MATCH(LARGE('All Recipes'!$K$2:$K$554,$G29),'All Recipes'!$K$2:$K$554,0)),IF($F29=3,INDEX('All Recipes'!$A$2:$A$554,MATCH(LARGE('All Recipes'!$L$2:$L$554,$G29),'All Recipes'!$L$2:$L$554,0)),""))),"")} | D29: {=IFERROR(IF($F29=1,INDEX('All Recipes'!$B$2:$B$554,MATCH(LARGE('All Recipes'!$J$2:$J$554,$G29),'All Recipes'!$J$2:$J$554,0)),IF($F29=2,INDEX('All Recipes'!$B$2:$B$554,MATCH(LARGE('All Recipes'!$K$2:$K$554,$G29),'All Recipes'!$K$2:$K$554,0)),IF($F29=3,INDEX('All Recipes'!$B$2:$B$554,MATCH(LARGE('All Recipes'!$L$2:$L$554,$G29),'All Recipes'!$L$2:$L$554,0)),""))),"")} | E29: {=IFERROR(IF($F29=1,INDEX('All Recipes'!$F$2:$F$554,MATCH(LARGE('All Recipes'!$J$2:$J$554,$G29),'All Recipes'!$J$2:$J$554,0)),IF($F29=2,INDEX('All Recipes'!$F$2:$F$554,MATCH(LARGE('All Recipes'!$K$2:$K$554,$G29),'All Recipes'!$K$2:$K$554,0)),IF($F29=3,INDEX('All Recipes'!$F$2:$F$554,MATCH(LARGE('All Recipes'!$L$2:$L$554,$G29),'All Recipes'!$L$2:$L$554,0)),""))),"")} | F29: =IF(2<=$B$6,1,IF(2<=$B$6+$C$6,2,IF(2<=$B$6+$C$6+$D$6,3,0))) | G29: =IF(2<=$B$6,2,IF(2<=$B$6+$C$6,2-$B$6,IF(2<=$B$6+$C$6+$D$6,2-$B$6-$C$6,0)))
A30: =IF($F30=0,"",3) | B30: =IF($F30=0,"",IF($F30=1,"Asian",IF($F30=2,"Chinese","Western"))) | C30: {=IFERROR(IF($F30=1,INDEX('All Recipes'!$A$2:$A$554,MATCH(LARGE('All Recipes'!$J$2:$J$554,$G30),'All Recipes'!$J$2:$J$554,0)),IF($F30=2,INDEX('All Recipes'!$A$2:$A$554,MATCH(LARGE('All Recipes'!$K$2:$K$554,$G30),'All Recipes'!$K$2:$K$554,0)),IF($F30=3,INDEX('All Recipes'!$A$2:$A$554,MATCH(LARGE('All Recipes'!$L$2:$L$554,$G30),'All Recipes'!$L$2:$L$554,0)),""))),"")} | D30: {=IFERROR(IF($F30=1,INDEX('All Recipes'!$B$2:$B$554,MATCH(LARGE('All Recipes'!$J$2:$J$554,$G30),'All Recipes'!$J$2:$J$554,0)),IF($F30=2,INDEX('All Recipes'!$B$2:$B$554,MATCH(LARGE('All Recipes'!$K$2:$K$554,$G30),'All Recipes'!$K$2:$K$554,0)),IF($F30=3,INDEX('All Recipes'!$B$2:$B$554,MATCH(LARGE('All Recipes'!$L$2:$L$554,$G30),'All Recipes'!$L$2:$L$554,0)),""))),"")} | E30: {=IFERROR(IF($F30=1,INDEX('All Recipes'!$F$2:$F$554,MATCH(LARGE('All Recipes'!$J$2:$J$554,$G30),'All Recipes'!$J$2:$J$554,0)),IF($F30=2,INDEX('All Recipes'!$F$2:$F$554,MATCH(LARGE('All Recipes'!$K$2:$K$554,$G30),'All Recipes'!$K$2:$K$554,0)),IF($F30=3,INDEX('All Recipes'!$F$2:$F$554,MATCH(LARGE('All Recipes'!$L$2:$L$554,$G30),'All Recipes'!$L$2:$L$554,0)),""))),"")} | F30: =IF(3<=$B$6,1,IF(3<=$B$6+$C$6,2,IF(3<=$B$6+$C$6+$D$6,3,0))) | G30: =IF(3<=$B$6,3,IF(3<=$B$6+$C$6,3-$B$6,IF(3<=$B$6+$C$6+$D$6,3-$B$6-$C$6,0)))
A31: =IF($F31=0,"",4) | B31: =IF($F31=0,"",IF($F31=1,"Asian",IF($F31=2,"Chinese","Western"))) | C31: {=IFERROR(IF($F31=1,INDEX('All Recipes'!$A$2:$A$554,MATCH(LARGE('All Recipes'!$J$2:$J$554,$G31),'All Recipes'!$J$2:$J$554,0)),IF($F31=2,INDEX('All Recipes'!$A$2:$A$554,MATCH(LARGE('All Recipes'!$K$2:$K$554,$G31),'All Recipes'!$K$2:$K$554,0)),IF($F31=3,INDEX('All Recipes'!$A$2:$A$554,MATCH(LARGE('All Recipes'!$L$2:$L$554,$G31),'All Recipes'!$L$2:$L$554,0)),""))),"")} | D31: {=IFERROR(IF($F31=1,INDEX('All Recipes'!$B$2:$B$554,MATCH(LARGE('All Recipes'!$J$2:$J$554,$G31),'All Recipes'!$J$2:$J$554,0)),IF($F31=2,INDEX('All Recipes'!$B$2:$B$554,MATCH(LARGE('All Recipes'!$K$2:$K$554,$G31),'All Recipes'!$K$2:$K$554,0)),IF($F31=3,INDEX('All Recipes'!$B$2:$B$554,MATCH(LARGE('All Recipes'!$L$2:$L$554,$G31),'All Recipes'!$L$2:$L$554,0)),""))),"")} | E31: {=IFERROR(IF($F31=1,INDEX('All Recipes'!$F$2:$F$554,MATCH(LARGE('All Recipes'!$J$2:$J$554,$G31),'All Recipes'!$J$2:$J$554,0)),IF($F31=2,INDEX('All Recipes'!$F$2:$F$554,MATCH(LARGE('All Recipes'!$K$2:$K$554,$G31),'All Recipes'!$K$2:$K$554,0)),IF($F31=3,INDEX('All Recipes'!$F$2:$F$554,MATCH(LARGE('All Recipes'!$L$2:$L$554,$G31),'All Recipes'!$L$2:$L$554,0)),""))),"")} | F31: =IF(4<=$B$6,1,IF(4<=$B$6+$C$6,2,IF(4<=$B$6+$C$6+$D$6,3,0))) | G31: =IF(4<=$B$6,4,IF(4<=$B$6+$C$6,4-$B$6,IF(4<=$B$6+$C$6+$D$6,4-$B$6-$C$6,0)))
A32: =IF($F32=0,"",5) | B32: =IF($F32=0,"",IF($F32=1,"Asian",IF($F32=2,"Chinese","Western"))) | C32: {=IFERROR(IF($F32=1,INDEX('All Recipes'!$A$2:$A$554,MATCH(LARGE('All Recipes'!$J$2:$J$554,$G32),'All Recipes'!$J$2:$J$554,0)),IF($F32=2,INDEX('All Recipes'!$A$2:$A$554,MATCH(LARGE('All Recipes'!$K$2:$K$554,$G32),'All Recipes'!$K$2:$K$554,0)),IF($F32=3,INDEX('All Recipes'!$A$2:$A$554,MATCH(LARGE('All Recipes'!$L$2:$L$554,$G32),'All Recipes'!$L$2:$L$554,0)),""))),"")} | D32: {=IFERROR(IF($F32=1,INDEX('All Recipes'!$B$2:$B$554,MATCH(LARGE('All Recipes'!$J$2:$J$554,$G32),'All Recipes'!$J$2:$J$554,0)),IF($F32=2,INDEX('All Recipes'!$B$2:$B$554,MATCH(LARGE('All Recipes'!$K$2:$K$554,$G32),'All Recipes'!$K$2:$K$554,0)),IF($F32=3,INDEX('All Recipes'!$B$2:$B$554,MATCH(LARGE('All Recipes'!$L$2:$L$554,$G32),'All Recipes'!$L$2:$L$554,0)),""))),"")} | E32: {=IFERROR(IF($F32=1,INDEX('All Recipes'!$F$2:$F$554,MATCH(LARGE('All Recipes'!$J$2:$J$554,$G32),'All Recipes'!$J$2:$J$554,0)),IF($F32=2,INDEX('All Recipes'!$F$2:$F$554,MATCH(LARGE('All Recipes'!$K$2:$K$554,$G32),'All Recipes'!$K$2:$K$554,0)),IF($F32=3,INDEX('All Recipes'!$F$2:$F$554,MATCH(LARGE('All Recipes'!$L$2:$L$554,$G32),'All Recipes'!$L$2:$L$554,0)),""))),"")} | F32: =IF(5<=$B$6,1,IF(5<=$B$6+$C$6,2,IF(5<=$B$6+$C$6+$D$6,3,0))) | G32: =IF(5<=$B$6,5,IF(5<=$B$6+$C$6,5-$B$6,IF(5<=$B$6+$C$6+$D$6,5-$B$6-$C$6,0)))
A33: =IF($F33=0,"",6) | B33: =IF($F33=0,"",IF($F33=1,"Asian",IF($F33=2,"Chinese","Western"))) | C33: {=IFERROR(IF($F33=1,INDEX('All Recipes'!$A$2:$A$554,MATCH(LARGE('All Recipes'!$J$2:$J$554,$G33),'All Recipes'!$J$2:$J$554,0)),IF($F33=2,INDEX('All Recipes'!$A$2:$A$554,MATCH(LARGE('All Recipes'!$K$2:$K$554,$G33),'All Recipes'!$K$2:$K$554,0)),IF($F33=3,INDEX('All Recipes'!$A$2:$A$554,MATCH(LARGE('All Recipes'!$L$2:$L$554,$G33),'All Recipes'!$L$2:$L$554,0)),""))),"")} | D33: {=IFERROR(IF($F33=1,INDEX('All Recipes'!$B$2:$B$554,MATCH(LARGE('All Recipes'!$J$2:$J$554,$G33),'All Recipes'!$J$2:$J$554,0)),IF($F33=2,INDEX('All Recipes'!$B$2:$B$554,MATCH(LARGE('All Recipes'!$K$2:$K$554,$G33),'All Recipes'!$K$2:$K$554,0)),IF($F33=3,INDEX('All Recipes'!$B$2:$B$554,MATCH(LARGE('All Recipes'!$L$2:$L$554,$G33),'All Recipes'!$L$2:$L$554,0)),""))),"")} | E33: {=IFERROR(IF($F33=1,INDEX('All Recipes'!$F$2:$F$554,MATCH(LARGE('All Recipes'!$J$2:$J$554,$G33),'All Recipes'!$J$2:$J$554,0)),IF($F33=2,INDEX('All Recipes'!$F$2:$F$554,MATCH(LARGE('All Recipes'!$K$2:$K$554,$G33),'All Recipes'!$K$2:$K$554,0)),IF($F33=3,INDEX('All Recipes'!$F$2:$F$554,MATCH(LARGE('All Recipes'!$L$2:$L$554,$G33),'All Recipes'!$L$2:$L$554,0)),""))),"")} | F33: =IF(6<=$B$6,1,IF(6<=$B$6+$C$6,2,IF(6<=$B$6+$C$6+$D$6,3,0))) | G33: =IF(6<=$B$6,6,IF(6<=$B$6+$C$6,6-$B$6,IF(6<=$B$6+$C$6+$D$6,6-$B$6-$C$6,0)))
A34: =IF($F34=0,"",7) | B34: =IF($F34=0,"",IF($F34=1,"Asian",IF($F34=2,"Chinese","Western"))) | C34: {=IFERROR(IF($F34=1,INDEX('All Recipes'!$A$2:$A$554,MATCH(LARGE('All Recipes'!$J$2:$J$554,$G34),'All Recipes'!$J$2:$J$554,0)),IF($F34=2,INDEX('All Recipes'!$A$2:$A$554,MATCH(LARGE('All Recipes'!$K$2:$K$554,$G34),'All Recipes'!$K$2:$K$554,0)),IF($F34=3,INDEX('All Recipes'!$A$2:$A$554,MATCH(LARGE('All Recipes'!$L$2:$L$554,$G34),'All Recipes'!$L$2:$L$554,0)),""))),"")} | D34: {=IFERROR(IF($F34=1,INDEX('All Recipes'!$B$2:$B$554,MATCH(LARGE('All Recipes'!$J$2:$J$554,$G34),'All Recipes'!$J$2:$J$554,0)),IF($F34=2,INDEX('All Recipes'!$B$2:$B$554,MATCH(LARGE('All Recipes'!$K$2:$K$554,$G34),'All Recipes'!$K$2:$K$554,0)),IF($F34=3,INDEX('All Recipes'!$B$2:$B$554,MATCH(LARGE('All Recipes'!$L$2:$L$554,$G34),'All Recipes'!$L$2:$L$554,0)),""))),"")} | E34: {=IFERROR(IF($F34=1,INDEX('All Recipes'!$F$2:$F$554,MATCH(LARGE('All Recipes'!$J$2:$J$554,$G34),'All Recipes'!$J$2:$J$554,0)),IF($F34=2,INDEX('All Recipes'!$F$2:$F$554,MATCH(LARGE('All Recipes'!$K$2:$K$554,$G34),'All Recipes'!$K$2:$K$554,0)),IF($F34=3,INDEX('All Recipes'!$F$2:$F$554,MATCH(LARGE('All Recipes'!$L$2:$L$554,$G34),'All Recipes'!$L$2:$L$554,0)),""))),"")} | F34: =IF(7<=$B$6,1,IF(7<=$B$6+$C$6,2,IF(7<=$B$6+$C$6+$D$6,3,0))) | G34: =IF(7<=$B$6,7,IF(7<=$B$6+$C$6,7-$B$6,IF(7<=$B$6+$C$6+$D$6,7-$B$6-$C$6,0)))
A35: =IF($F35=0,"",8) | B35: =IF($F35=0,"",IF($F35=1,"Asian",IF($F35=2,"Chinese","Western"))) | C35: {=IFERROR(IF($F35=1,INDEX('All Recipes'!$A$2:$A$554,MATCH(LARGE('All Recipes'!$J$2:$J$554,$G35),'All Recipes'!$J$2:$J$554,0)),IF($F35=2,INDEX('All Recipes'!$A$2:$A$554,MATCH(LARGE('All Recipes'!$K$2:$K$554,$G35),'All Recipes'!$K$2:$K$554,0)),IF($F35=3,INDEX('All Recipes'!$A$2:$A$554,MATCH(LARGE('All Recipes'!$L$2:$L$554,$G35),'All Recipes'!$L$2:$L$554,0)),""))),"")} | D35: {=IFERROR(IF($F35=1,INDEX('All Recipes'!$B$2:$B$554,MATCH(LARGE('All Recipes'!$J$2:$J$554,$G35),'All Recipes'!$J$2:$J$554,0)),IF($F35=2,INDEX('All Recipes'!$B$2:$B$554,MATCH(LARGE('All Recipes'!$K$2:$K$554,$G35),'All Recipes'!$K$2:$K$554,0)),IF($F35=3,INDEX('All Recipes'!$B$2:$B$554,MATCH(LARGE('All Recipes'!$L$2:$L$554,$G35),'All Recipes'!$L$2:$L$554,0)),""))),"")} | E35: {=IFERROR(IF($F35=1,INDEX('All Recipes'!$F$2:$F$554,MATCH(LARGE('All Recipes'!$J$2:$J$554,$G35),'All Recipes'!$J$2:$J$554,0)),IF($F35=2,INDEX('All Recipes'!$F$2:$F$554,MATCH(LARGE('All Recipes'!$K$2:$K$554,$G35),'All Recipes'!$K$2:$K$554,0)),IF($F35=3,INDEX('All Recipes'!$F$2:$F$554,MATCH(LARGE('All Recipes'!$L$2:$L$554,$G35),'All Recipes'!$L$2:$L$554,0)),""))),"")} | F35: =IF(8<=$B$6,1,IF(8<=$B$6+$C$6,2,IF(8<=$B$6+$C$6+$D$6,3,0))) | G35: =IF(8<=$B$6,8,IF(8<=$B$6+$C$6,8-$B$6,IF(8<=$B$6+$C$6+$D$6,8-$B$6-$C$6,0)))
A36: =IF($F36=0,"",9) | B36: =IF($F36=0,"",IF($F36=1,"Asian",IF($F36=2,"Chinese","Western"))) | C36: {=IFERROR(IF($F36=1,INDEX('All Recipes'!$A$2:$A$554,MATCH(LARGE('All Recipes'!$J$2:$J$554,$G36),'All Recipes'!$J$2:$J$554,0)),IF($F36=2,INDEX('All Recipes'!$A$2:$A$554,MATCH(LARGE('All Recipes'!$K$2:$K$554,$G36),'All Recipes'!$K$2:$K$554,0)),IF($F36=3,INDEX('All Recipes'!$A$2:$A$554,MATCH(LARGE('All Recipes'!$L$2:$L$554,$G36),'All Recipes'!$L$2:$L$554,0)),""))),"")} | D36: {=IFERROR(IF($F36=1,INDEX('All Recipes'!$B$2:$B$554,MATCH(LARGE('All Recipes'!$J$2:$J$554,$G36),'All Recipes'!$J$2:$J$554,0)),IF($F36=2,INDEX('All Recipes'!$B$2:$B$554,MATCH(LARGE('All Recipes'!$K$2:$K$554,$G36),'All Recipes'!$K$2:$K$554,0)),IF($F36=3,INDEX('All Recipes'!$B$2:$B$554,MATCH(LARGE('All Recipes'!$L$2:$L$554,$G36),'All Recipes'!$L$2:$L$554,0)),""))),"")} | E36: {=IFERROR(IF($F36=1,INDEX('All Recipes'!$F$2:$F$554,MATCH(LARGE('All Recipes'!$J$2:$J$554,$G36),'All Recipes'!$J$2:$J$554,0)),IF($F36=2,INDEX('All Recipes'!$F$2:$F$554,MATCH(LARGE('All Recipes'!$K$2:$K$554,$G36),'All Recipes'!$K$2:$K$554,0)),IF($F36=3,INDEX('All Recipes'!$F$2:$F$554,MATCH(LARGE('All Recipes'!$L$2:$L$554,$G36),'All Recipes'!$L$2:$L$554,0)),""))),"")} | F36: =IF(9<=$B$6,1,IF(9<=$B$6+$C$6,2,IF(9<=$B$6+$C$6+$D$6,3,0))) | G36: =IF(9<=$B$6,9,IF(9<=$B$6+$C$6,9-$B$6,IF(9<=$B$6+$C$6+$D$6,9-$B$6-$C$6,0)))
A37: =IF($F37=0,"",10) | B37: =IF($F37=0,"",IF($F37=1,"Asian",IF($F37=2,"Chinese","Western"))) | C37: {=IFERROR(IF($F37=1,INDEX('All Recipes'!$A$2:$A$554,MATCH(LARGE('All Recipes'!$J$2:$J$554,$G37),'All Recipes'!$J$2:$J$554,0)),IF($F37=2,INDEX('All Recipes'!$A$2:$A$554,MATCH(LARGE('All Recipes'!$K$2:$K$554,$G37),'All Recipes'!$K$2:$K$554,0)),IF($F37=3,INDEX('All Recipes'!$A$2:$A$554,MATCH(LARGE('All Recipes'!$L$2:$L$554,$G37),'All Recipes'!$L$2:$L$554,0)),""))),"")} | D37: {=IFERROR(IF($F37=1,INDEX('All Recipes'!$B$2:$B$554,MATCH(LARGE('All Recipes'!$J$2:$J$554,$G37),'All Recipes'!$J$2:$J$554,0)),IF($F37=2,INDEX('All Recipes'!$B$2:$B$554,MATCH(LARGE('All Recipes'!$K$2:$K$554,$G37),'All Recipes'!$K$2:$K$554,0)),IF($F37=3,INDEX('All Recipes'!$B$2:$B$554,MATCH(LARGE('All Recipes'!$L$2:$L$554,$G37),'All Recipes'!$L$2:$L$554,0)),""))),"")} | E37: {=IFERROR(IF($F37=1,INDEX('All Recipes'!$F$2:$F$554,MATCH(LARGE('All Recipes'!$J$2:$J$554,$G37),'All Recipes'!$J$2:$J$554,0)),IF($F37=2,INDEX('All Recipes'!$F$2:$F$554,MATCH(LARGE('All Recipes'!$K$2:$K$554,$G37),'All Recipes'!$K$2:$K$554,0)),IF($F37=3,INDEX('All Recipes'!$F$2:$F$554,MATCH(LARGE('All Recipes'!$L$2:$L$554,$G37),'All Recipes'!$L$2:$L$554,0)),""))),"")} | F37: =IF(10<=$B$6,1,IF(10<=$B$6+$C$6,2,IF(10<=$B$6+$C$6+$D$6,3,0))) | G37: =IF(10<=$B$6,10,IF(10<=$B$6+$C$6,10-$B$6,IF(10<=$B$6+$C$6+$D$6,10-$B$6-$C$6,0)))
A38: =IF($F38=0,"",11) | B38: =IF($F38=0,"",IF($F38=1,"Asian",IF($F38=2,"Chinese","Western"))) | C38: {=IFERROR(IF($F38=1,INDEX('All Recipes'!$A$2:$A$554,MATCH(LARGE('All Recipes'!$J$2:$J$554,$G38),'All Recipes'!$J$2:$J$554,0)),IF($F38=2,INDEX('All Recipes'!$A$2:$A$554,MATCH(LARGE('All Recipes'!$K$2:$K$554,$G38),'All Recipes'!$K$2:$K$554,0)),IF($F38=3,INDEX('All Recipes'!$A$2:$A$554,MATCH(LARGE('All Recipes'!$L$2:$L$554,$G38),'All Recipes'!$L$2:$L$554,0)),""))),"")} | D38: {=IFERROR(IF($F38=1,INDEX('All Recipes'!$B$2:$B$554,MATCH(LARGE('All Recipes'!$J$2:$J$554,$G38),'All Recipes'!$J$2:$J$554,0)),IF($F38=2,INDEX('All Recipes'!$B$2:$B$554,MATCH(LARGE('All Recipes'!$K$2:$K$554,$G38),'All Recipes'!$K$2:$K$554,0)),IF($F38=3,INDEX('All Recipes'!$B$2:$B$554,MATCH(LARGE('All Recipes'!$L$2:$L$554,$G38),'All Recipes'!$L$2:$L$554,0)),""))),"")} | E38: {=IFERROR(IF($F38=1,INDEX('All Recipes'!$F$2:$F$554,MATCH(LARGE('All Recipes'!$J$2:$J$554,$G38),'All Recipes'!$J$2:$J$554,0)),IF($F38=2,INDEX('All Recipes'!$F$2:$F$554,MATCH(LARGE('All Recipes'!$K$2:$K$554,$G38),'All Recipes'!$K$2:$K$554,0)),IF($F38=3,INDEX('All Recipes'!$F$2:$F$554,MATCH(LARGE('All Recipes'!$L$2:$L$554,$G38),'All Recipes'!$L$2:$L$554,0)),""))),"")} | F38: =IF(11<=$B$6,1,IF(11<=$B$6+$C$6,2,IF(11<=$B$6+$C$6+$D$6,3,0))) | G38: =IF(11<=$B$6,11,IF(11<=$B$6+$C$6,11-$B$6,IF(11<=$B$6+$C$6+$D$6,11-$B$6-$C$6,0)))
A39: =IF($F39=0,"",12) | B39: =IF($F39=0,"",IF($F39=1,"Asian",IF($F39=2,"Chinese","Western"))) | C39: {=IFERROR(IF($F39=1,INDEX('All Recipes'!$A$2:$A$554,MATCH(LARGE('All Recipes'!$J$2:$J$554,$G39),'All Recipes'!$J$2:$J$554,0)),IF($F39=2,INDEX('All Recipes'!$A$2:$A$554,MATCH(LARGE('All Recipes'!$K$2:$K$554,$G39),'All Recipes'!$K$2:$K$554,0)),IF($F39=3,INDEX('All Recipes'!$A$2:$A$554,MATCH(LARGE('All Recipes'!$L$2:$L$554,$G39),'All Recipes'!$L$2:$L$554,0)),""))),"")} | D39: {=IFERROR(IF($F39=1,INDEX('All Recipes'!$B$2:$B$554,MATCH(LARGE('All Recipes'!$J$2:$J$554,$G39),'All Recipes'!$J$2:$J$554,0)),IF($F39=2,INDEX('All Recipes'!$B$2:$B$554,MATCH(LARGE('All Recipes'!$K$2:$K$554,$G39),'All Recipes'!$K$2:$K$554,0)),IF($F39=3,INDEX('All Recipes'!$B$2:$B$554,MATCH(LARGE('All Recipes'!$L$2:$L$554,$G39),'All Recipes'!$L$2:$L$554,0)),""))),"")} | E39: {=IFERROR(IF($F39=1,INDEX('All Recipes'!$F$2:$F$554,MATCH(LARGE('All Recipes'!$J$2:$J$554,$G39),'All Recipes'!$J$2:$J$554,0)),IF($F39=2,INDEX('All Recipes'!$F$2:$F$554,MATCH(LARGE('All Recipes'!$K$2:$K$554,$G39),'All Recipes'!$K$2:$K$554,0)),IF($F39=3,INDEX('All Recipes'!$F$2:$F$554,MATCH(LARGE('All Recipes'!$L$2:$L$554,$G39),'All Recipes'!$L$2:$L$554,0)),""))),"")} | F39: =IF(12<=$B$6,1,IF(12<=$B$6+$C$6,2,IF(12<=$B$6+$C$6+$D$6,3,0))) | G39: =IF(12<=$B$6,12,IF(12<=$B$6+$C$6,12-$B$6,IF(12<=$B$6+$C$6+$D$6,12-$B$6-$C$6,0)))
A41: 🍲 DINNER
A42: # | B42: Cuisine | C42: Recipe | D42: Ingredients | E42: Recipe link
A43: =IF($F43=0,"",1) | B43: =IF($F43=0,"",IF($F43=1,"Asian",IF($F43=2,"Chinese","Western"))) | C43: {=IFERROR(IF($F43=1,INDEX('All Recipes'!$A$2:$A$554,MATCH(LARGE('All Recipes'!$M$2:$M$554,$G43),'All Recipes'!$M$2:$M$554,0)),IF($F43=2,INDEX('All Recipes'!$A$2:$A$554,MATCH(LARGE('All Recipes'!$N$2:$N$554,$G43),'All Recipes'!$N$2:$N$554,0)),IF($F43=3,INDEX('All Recipes'!$A$2:$A$554,MATCH(LARGE('All Recipes'!$O$2:$O$554,$G43),'All Recipes'!$O$2:$O$554,0)),""))),"")} | D43: {=IFERROR(IF($F43=1,INDEX('All Recipes'!$B$2:$B$554,MATCH(LARGE('All Recipes'!$M$2:$M$554,$G43),'All Recipes'!$M$2:$M$554,0)),IF($F43=2,INDEX('All Recipes'!$B$2:$B$554,MATCH(LARGE('All Recipes'!$N$2:$N$554,$G43),'All Recipes'!$N$2:$N$554,0)),IF($F43=3,INDEX('All Recipes'!$B$2:$B$554,MATCH(LARGE('All Recipes'!$O$2:$O$554,$G43),'All Recipes'!$O$2:$O$554,0)),""))),"")} | E43: {=IFERROR(IF($F43=1,INDEX('All Recipes'!$F$2:$F$554,MATCH(LARGE('All Recipes'!$M$2:$M$554,$G43),'All Recipes'!$M$2:$M$554,0)),IF($F43=2,INDEX('All Recipes'!$F$2:$F$554,MATCH(LARGE('All Recipes'!$N$2:$N$554,$G43),'All Recipes'!$N$2:$N$554,0)),IF($F43=3,INDEX('All Recipes'!$F$2:$F$554,MATCH(LARGE('All Recipes'!$O$2:$O$554,$G43),'All Recipes'!$O$2:$O$554,0)),""))),"")} | F43: =IF(1<=$B$7,1,IF(1<=$B$7+$C$7,2,IF(1<=$B$7+$C$7+$D$7,3,0))) | G43: =IF(1<=$B$7,1,IF(1<=$B$7+$C$7,1-$B$7,IF(1<=$B$7+$C$7+$D$7,1-$B$7-$C$7,0)))
A44: =IF($F44=0,"",2) | B44: =IF($F44=0,"",IF($F44=1,"Asian",IF($F44=2,"Chinese","Western"))) | C44: {=IFERROR(IF($F44=1,INDEX('All Recipes'!$A$2:$A$554,MATCH(LARGE('All Recipes'!$M$2:$M$554,$G44),'All Recipes'!$M$2:$M$554,0)),IF($F44=2,INDEX('All Recipes'!$A$2:$A$554,MATCH(LARGE('All Recipes'!$N$2:$N$554,$G44),'All Recipes'!$N$2:$N$554,0)),IF($F44=3,INDEX('All Recipes'!$A$2:$A$554,MATCH(LARGE('All Recipes'!$O$2:$O$554,$G44),'All Recipes'!$O$2:$O$554,0)),""))),"")} | D44: {=IFERROR(IF($F44=1,INDEX('All Recipes'!$B$2:$B$554,MATCH(LARGE('All Recipes'!$M$2:$M$554,$G44),'All Recipes'!$M$2:$M$554,0)),IF($F44=2,INDEX('All Recipes'!$B$2:$B$554,MATCH(LARGE('All Recipes'!$N$2:$N$554,$G44),'All Recipes'!$N$2:$N$554,0)),IF($F44=3,INDEX('All Recipes'!$B$2:$B$554,MATCH(LARGE('All Recipes'!$O$2:$O$554,$G44),'All Recipes'!$O$2:$O$554,0)),""))),"")} | E44: {=IFERROR(IF($F44=1,INDEX('All Recipes'!$F$2:$F$554,MATCH(LARGE('All Recipes'!$M$2:$M$554,$G44),'All Recipes'!$M$2:$M$554,0)),IF($F44=2,INDEX('All Recipes'!$F$2:$F$554,MATCH(LARGE('All Recipes'!$N$2:$N$554,$G44),'All Recipes'!$N$2:$N$554,0)),IF($F44=3,INDEX('All Recipes'!$F$2:$F$554,MATCH(LARGE('All Recipes'!$O$2:$O$554,$G44),'All Recipes'!$O$2:$O$554,0)),""))),"")} | F44: =IF(2<=$B$7,1,IF(2<=$B$7+$C$7,2,IF(2<=$B$7+$C$7+$D$7,3,0))) | G44: =IF(2<=$B$7,2,IF(2<=$B$7+$C$7,2-$B$7,IF(2<=$B$7+$C$7+$D$7,2-$B$7-$C$7,0)))
...

Sheet All Recipes
A1: Recipe | B1: Ingredients | C1: Meal Type | D1: Cuisine | E1: Confidence | F1: Link | G1: bA | H1: bC | I1: bW | J1: lA | K1: lC | L1: lW | M1: dA | N1: dC | O1: dW | P1: Soup
A2: 4 bean stir fry | B2: Pinto Beans, Sweet Corn Can, Green bell pepper, Onion, Paprika | C2: Dinner | D2: Chinese | E2: Med | F2: https://www.kitchenstories.com/en/recipes/4-ingredient-bean-stir-fry-c72f | G2: =IF(AND(ISNUMBER(SEARCH("Breakfast",$C2)),$D2="Asian"),RAND(),"") | H2: =IF(AND(ISNUMBER(SEARCH("Breakfast",$C2)),$D2="Chinese"),RAND(),"") | I2: =IF(AND(ISNUMBER(SEARCH("Breakfast",$C2)),$D2="Western"),RAND(),"") | J2: =IF(AND(ISNUMBER(SEARCH("Lunch",$C2)),$D2="Asian"),RAND(),"") | K2: =IF(AND(ISNUMBER(SEARCH("Lunch",$C2)),$D2="Chinese"),RAND(),"") | L2: =IF(AND(ISNUMBER(SEARCH("Lunch",$C2)),$D2="Western"),RAND(),"") | M2: =IF(AND(ISNUMBER(SEARCH("Dinner",$C2)),$D2="Asian"),RAND(),"") | N2: =IF(AND(ISNUMBER(SEARCH("Dinner",$C2)),$D2="Chinese"),RAND(),"") | O2: =IF(AND(ISNUMBER(SEARCH("Dinner",$C2)),$D2="Western"),RAND(),"")
A3: A1 BKT | B3: Soup Pack, 西施骨, 猪筒骨, Garlic, Soy Sauce | C3: Dinner | D3: Chinese | E3: High | G3: =IF(AND(ISNUMBER(SEARCH("Breakfast",$C3)),$D3="Asian"),RAND(),"") | H3: =IF(AND(ISNUMBER(SEARCH("Breakfast",$C3)),$D3="Chinese"),RAND(),"") | I3: =IF(AND(ISNUMBER(SEARCH("Breakfast",$C3)),$D3="Western"),RAND(),"") | J3: =IF(AND(ISNUMBER(SEARCH("Lunch",$C3)),$D3="Asian"),RAND(),"") | K3: =IF(AND(ISNUMBER(SEARCH("Lunch",$C3)),$D3="Chinese"),RAND(),"") | L3: =IF(AND(ISNUMBER(SEARCH("Lunch",$C3)),$D3="Western"),RAND(),"") | M3: =IF(AND(ISNUMBER(SEARCH("Dinner",$C3)),$D3="Asian"),RAND(),"") | N3: =IF(AND(ISNUMBER(SEARCH("Dinner",$C3)),$D3="Chinese"),RAND(),"") | O3: =IF(AND(ISNUMBER(SEARCH("Dinner",$C3)),$D3="Western"),RAND(),"")
A4: A1 chicken Soup | B4: Chicken Thigh, Chicken Soup Pack, Garlic, Soy Sauce, Oyster Sauce | C4: Dinner | D4: Chinese | E4: Med | G4: =IF(AND(ISNUMBER(SEARCH("Breakfast",$C4)),$D4="Asian"),RAND(),"") | H4: =IF(AND(ISNUMBER(SEARCH("Breakfast",$C4)),$D4="Chinese"),RAND(),"") | I4: =IF(AND(ISNUMBER(SEARCH("Breakfast",$C4)),$D4="Western"),RAND(),"") | J4: =IF(AND(ISNUMBER(SEARCH("Lunch",$C4)),$D4="Asian"),RAND(),"") | K4: =IF(AND(ISNUMBER(SEARCH("Lunch",$C4)),$D4="Chinese"),RAND(),"") | L4: =IF(AND(ISNUMBER(SEARCH("Lunch",$C4)),$D4="Western"),RAND(),"") | M4: =IF(AND(ISNUMBER(SEARCH("Dinner",$C4)),$D4="Asian"),RAND(),"") | N4: =IF(AND(ISNUMBER(SEARCH("Dinner",$C4)),$D4="Chinese"),RAND(),"") | O4: =IF(AND(ISNUMBER(SEARCH("Dinner",$C4)),$D4="Western"),RAND(),"") | P4: TRUE
A5: Abalone Shredded Chicken | B5: canned abalone, Chicken Thigh, Rice, Fried Shallots, Soy Sauce, Spring Onion, Coriander | C5: Dinner | D5: Chinese | E5: Med | F5: https://www.instagram.com/reel/DFpctMSp2HZ/?igsh=MWo5dDZiY3E4ZXRiZg== | G5: =IF(AND(ISNUMBER(SEARCH("Breakfast",$C5)),$D5="Asian"),RAND(),"") | H5: =IF(AND(ISNUMBER(SEARCH("Breakfast",$C5)),$D5="Chinese"),RAND(),"") | I5: =IF(AND(ISNUMBER(SEARCH("Breakfast",$C5)),$D5="Western"),RAND(),"") | J5: =IF(AND(ISNUMBER(SEARCH("Lunch",$C5)),$D5="Asian"),RAND(),"") | K5: =IF(AND(ISNUMBER(SEARCH("Lunch",$C5)),$D5="Chinese"),RAND(),"") | L5: =IF(AND(ISNUMBER(SEARCH("Lunch",$C5)),$D5="Western"),RAND(),"") | M5: =IF(AND(ISNUMBER(SEARCH("Dinner",$C5)),$D5="Asian"),RAND(),"") | N5: =IF(AND(ISNUMBER(SEARCH("Dinner",$C5)),$D5="Chinese"),RAND(),"") | O5: =IF(AND(ISNUMBER(SEARCH("Dinner",$C5)),$D5="Western"),RAND(),"")
A6: ABC soup | B6: — | C6: Dinner | D6: Chinese | E6: Low | G6: =IF(AND(ISNUMBER(SEARCH("Breakfast",$C6)),$D6="Asian"),RAND(),"") | H6: =IF(AND(ISNUMBER(SEARCH("Breakfast",$C6)),$D6="Chinese"),RAND(),"") | I6: =IF(AND(ISNUMBER(SEARCH("Breakfast",$C6)),$D6="Western"),RAND(),"") | J6: =IF(AND(ISNUMBER(SEARCH("Lunch",$C6)),$D6="Asian"),RAND(),"") | K6: =IF(AND(ISNUMBER(SEARCH("Lunch",$C6)),$D6="Chinese"),RAND(),"") | L6: =IF(AND(ISNUMBER(SEARCH("Lunch",$C6)),$D6="Western"),RAND(),"") | M6: =IF(AND(ISNUMBER(SEARCH("Dinner",$C6)),$D6="Asian"),RAND(),"") | N6: =IF(AND(ISNUMBER(SEARCH("Dinner",$C6)),$D6="Chinese"),RAND(),"") | O6: =IF(AND(ISNUMBER(SEARCH("Dinner",$C6)),$D6="Western"),RAND(),"") | P6: TRUE
A7: Agedashi Tofu | B7: Tofu, Green Onion, Ginger, Mirin, Dashi Powder, Potato Starch | C7: Dinner | D7: Asian | E7: High | F7: https://youtu.be/70AR0pCcaT4 | G7: =IF(AND(ISNUMBER(SEARCH("Breakfast",$C7)),$D7="Asian"),RAND(),"") | H7: =IF(AND(ISNUMBER(SEARCH("Breakfast",$C7)),$D7="Chinese"),RAND(),"") | I7: =IF(AND(ISNUMBER(SEARCH("Breakfast",$C7)),$D7="Western"),RAND(),"") | J7: =IF(AND(ISNUMBER(SEARCH("Lunch",$C7)),$D7="Asian"),RAND(),"") | K7: =IF(AND(ISNUMBER(SEARCH("Lunch",$C7)),$D7="Chinese"),RAND(),"") | L7: =IF(AND(ISNUMBER(SEARCH("Lunch",$C7)),$D7="Western"),RAND(),"") | M7: =IF(AND(ISNUMBER(SEARCH("Dinner",$C7)),$D7="Asian"),RAND(),"") | N7: =IF(AND(ISNUMBER(SEARCH("Dinner",$C7)),$D7="Chinese"),RAND(),"") | O7: =IF(AND(ISNUMBER(SEARCH("Dinner",$C7)),$D7="Western"),RAND(),"")
A8: Agile Olio | B8: Spaghetti, Garlic, Parmasean Cheese | C8: Dinner | D8: Western | E8: Med | F8: https://www.instagram.com/reel/DAnDsuftWKb/?igsh=MjFmNnhpeDducWdv | G8: =IF(AND(ISNUMBER(SEARCH("Breakfast",$C8)),$D8="Asian"),RAND(),"") | H8: =IF(AND(ISNUMBER(SEARCH("Breakfast",$C8)),$D8="Chinese"),RAND(),"") | I8: =IF(AND(ISNUMBER(SEARCH("Breakfast",$C8)),$D8="Western"),RAND(),"") | J8: =IF(AND(ISNUMBER(SEARCH("Lunch",$C8)),$D8="Asian"),RAND(),"") | K8: =IF(AND(ISNUMBER(SEARCH("Lunch",$C8)),$D8="Chinese"),RAND(),"") | L8: =IF(AND(ISNUMBER(SEARCH("Lunch",$C8)),$D8="Western"),RAND(),"") | M8: =IF(AND(ISNUMBER(SEARCH("Dinner",$C8)),$D8="Asian"),RAND(),"") | N8: =IF(AND(ISNUMBER(SEARCH("Dinner",$C8)),$D8="Chinese"),RAND(),"") | O8: =IF(AND(ISNUMBER(SEARCH("Dinner",$C8)),$D8="Western"),RAND(),"")
A9: Agilo Olio | B9: Spaghetti, Garlic, Parsley, Cheese, Shrimp | C9: Dinner | D9: Western | E9: Med | F9: https://www.instagram.com/reel/DAn-B95S1Uo/?igsh=MW03cGN0dDRud3Vzdw== | G9: =IF(AND(ISNUMBER(SEARCH("Breakfast",$C9)),$D9="Asian"),RAND(),"") | H9: =IF(AND(ISNUMBER(SEARCH("Breakfast",$C9)),$D9="Chinese"),RAND(),"") | I9: =IF(AND(ISNUMBER(SEARCH("Breakfast",$C9)),$D9="Western"),RAND(),"") | J9: =IF(AND(ISNUMBER(SEARCH("Lunch",$C9)),$D9="Asian"),RAND(),"") | K9: =IF(AND(ISNUMBER(SEARCH("Lunch",$C9)),$D9="Chinese"),RAND(),"") | L9: =IF(AND(ISNUMBER(SEARCH("Lunch",$C9)),$D9="Western"),RAND(),"") | M9: =IF(AND(ISNUMBER(SEARCH("Dinner",$C9)),$D9="Asian"),RAND(),"") | N9: =IF(AND(ISNUMBER(SEARCH("Dinner",$C9)),$D9="Chinese"),RAND(),"") | O9: =IF(AND(ISNUMBER(SEARCH("Dinner",$C9)),$D9="Western"),RAND(),"")
A10: Almond Milk Miso Soup | B10: Almond Milk, Miso, Small Yam, Enoki Mushroom, 杏鲍菇 | C10: Dinner | D10: Asian | E10: Med | F10: https://www.instagram.com/reel/C8vemJzP1Fc/?igsh=YWRobDFnZWIxam4w | G10: =IF(AND(ISNUMBER(SEARCH("Breakfast",$C10)),$D10="Asian"),RAND(),"") | H10: =IF(AND(ISNUMBER(SEARCH("Breakfast",$C10)),$D10="Chinese"),RAND(),"") | I10: =IF(AND(ISNUMBER(SEARCH("Breakfast",$C10)),$D10="Western"),RAND(),"") | J10: =IF(AND(ISNUMBER(SEARCH("Lunch",$C10)),$D10="Asian"),RAND(),"") | K10: =IF(AND(ISNUMBER(SEARCH("Lunch",$C10)),$D10="Chinese"),RAND(),"") | L10: =IF(AND(ISNUMBER(SEARCH("Lunch",$C10)),$D10="Western"),RAND(),"") | M10: =IF(AND(ISNUMBER(SEARCH("Dinner",$C10)),$D10="Asian"),RAND(),"") | N10: =IF(AND(ISNUMBER(SEARCH("Dinner",$C10)),$D10="Chinese"),RAND(),"") | O10: =IF(AND(ISNUMBER(SEARCH("Dinner",$C10)),$D10="Western"),RAND(),"") | P10: TRUE
A11: Asparangus | B11: Virgin Oliveoil, salt, black pepper, Vege | C11: Dinner | D11: Western | E11: Low | F11: https://youtu.be/VVKtYsxkrL4 | G11: =IF(AND(ISNUMBER(SEARCH("Breakfast",$C11)),$D11="Asian"),RAND(),"") | H11: =IF(AND(ISNUMBER(SEARCH("Breakfast",$C11)),$D11="Chinese"),RAND(),"") | I11: =IF(AND(ISNUMBER(SEARCH("Breakfast",$C11)),$D11="Western"),RAND(),"") | J11: =IF(AND(ISNUMBER(SEARCH("Lunch",$C11)),$D11="Asian"),RAND(),"") | K11: =IF(AND(ISNUMBER(SEARCH("Lunch",$C11)),$D11="Chinese"),RAND(),"") | L11: =IF(AND(ISNUMBER(SEARCH("Lunch",$C11)),$D11="Western"),RAND(),"") | M11: =IF(AND(ISNUMBER(SEARCH("Dinner",$C11)),$D11="Asian"),RAND(),"") | N11: =IF(AND(ISNUMBER(SEARCH("Dinner",$C11)),$D11="Chinese"),RAND(),"") | O11: =IF(AND(ISNUMBER(SEARCH("Dinner",$C11)),$D11="Western"),RAND(),"")
A12: Avocado Prawn salad | B12: — | C12: Lunch | D12: Western | E12: Med | G12: =IF(AND(ISNUMBER(SEARCH("Breakfast",$C12)),$D12="Asian"),RAND(),"") | H12: =IF(AND(ISNUMBER(SEARCH("Breakfast",$C12)),$D12="Chinese"),RAND(),"") | I12: =IF(AND(ISNUMBER(SEARCH("Breakfast",$C12)),$D12="Western"),RAND(),"") | J12: =IF(AND(ISNUMBER(SEARCH("Lunch",$C12)),$D12="Asian"),RAND(),"") | K12: =IF(AND(ISNUMBER(SEARCH("Lunch",$C12)),$D12="Chinese"),RAND(),"") | L12: =IF(AND(ISNUMBER(SEARCH("Lunch",$C12)),$D12="Western"),RAND(),"") | M12: =IF(AND(ISNUMBER(SEARCH("Dinner",$C12)),$D12="Asian"),RAND(),"") | N12: =IF(AND(ISNUMBER(SEARCH("Dinner",$C12)),$D12="Chinese"),RAND(),"") | O12: =IF(AND(ISNUMBER(SEARCH("Dinner",$C12)),$D12="Western"),RAND(),"")
A13: Avocado Tofu | B13: Avocado, Tofu, Wasabi, Soya Sauce, Sesame | C13: Dinner | D13: Chinese | E13: Med | F13: http://xhslink.com/OsHmJq | G13: =IF(AND(ISNUMBER(SEARCH("Breakfast",$C13)),$D13="Asian"),RAND(),"") | H13: =IF(AND(ISNUMBER(SEARCH("Breakfast",$C13)),$D13="Chinese"),RAND(),"") | I13: =IF(AND(ISNUMBER(SEARCH("Breakfast",$C13)),$D13="Western"),RAND(),"") | J13: =IF(AND(ISNUMBER(SEARCH("Lunch",$C13)),$D13="Asian"),RAND(),"") | K13: =IF(AND(ISNUMBER(SEARCH("Lunch",$C13)),$D13="Chinese"),RAND(),"") | L13: =IF(AND(ISNUMBER(SEARCH("Lunch",$C13)),$D13="Western"),RAND(),"") | M13: =IF(AND(ISNUMBER(SEARCH("Dinner",$C13)),$D13="Asian"),RAND(),"") | N13: =IF(AND(ISNUMBER(SEARCH("Dinner",$C13)),$D13="Chinese"),RAND(),"") | O13: =IF(AND(ISNUMBER(SEARCH("Dinner",$C13)),$D13="Western"),RAND(),"")
A14: Ayam Bakar | B14: — | C14: Dinner | D14: Asian | E14: Med | G14: =IF(AND(ISNUMBER(SEARCH("Breakfast",$C14)),$D14="Asian"),RAND(),"") | H14: =IF(AND(ISNUMBER(SEARCH("Breakfast",$C14)),$D14="Chinese"),RAND(),"") | I14: =IF(AND(ISNUMBER(SEARCH("Breakfast",$C14)),$D14="Western"),RAND(),"") | J14: =IF(AND(ISNUMBER(SEARCH("Lunch",$C14)),$D14="Asian"),RAND(),"") | K14: =IF(AND(ISNUMBER(SEARCH("Lunch",$C14)),$D14="Chinese"),RAND(),"") | L14: =IF(AND(ISNUMBER(SEARCH("Lunch",$C14)),$D14="Western"),RAND(),"") | M14: =IF(AND(ISNUMBER(SEARCH("Dinner",$C14)),$D14="Asian"),RAND(),"") | N14: =IF(AND(ISNUMBER(SEARCH("Dinner",$C14)),$D14="Chinese"),RAND(),"") | O14: =IF(AND(ISNUMBER(SEARCH("Dinner",$C14)),$D14="Western"),RAND(),"")
A15: Ayam Soto | B15: — | C15: Lunch | D15: Asian | E15: High | G15: =IF(AND(ISNUMBER(SEARCH("Breakfast",$C15)),$D15="Asian"),RAND(),"") | H15: =IF(AND(ISNUMBER(SEARCH("Breakfast",$C15)),$D15="Chinese"),RAND(),"") | I15: =IF(AND(ISNUMBER(SEARCH("Breakfast",$C15)),$D15="Western"),RAND(),"") | J15: =IF(AND(ISNUMBER(SEARCH("Lunch",$C15)),$D15="Asian"),RAND(),"") | K15: =IF(AND(ISNUMBER(SEARCH("Lunch",$C15)),$D15="Chinese"),RAND(),"") | L15: =IF(AND(ISNUMBER(SEARCH("Lunch",$C15)),$D15="Western"),RAND(),"") | M15: =IF(AND(ISNUMBER(SEARCH("Dinner",$C15)),$D15="Asian"),RAND(),"") | N15: =IF(AND(ISNUMBER(SEARCH("Dinner",$C15)),$D15="Chinese"),RAND(),"") | O15: =IF(AND(ISNUMBER(SEARCH("Dinner",$C15)),$D15="Western"),RAND(),"")
A16: Baba Ganosh | B16: Eggplants, Garlic, Tahini, Lemon, Greek Yoghurt, Olive Oil, Sea Salt, Sesame Seed, Fried Shallots | C16: Lunch | D16: Western | E16: Med | F16: https://www.instagram.com/reel/DJbY5amhoD_/?igsh=dWxmMWpseHFpZHg2 | G16: =IF(AND(ISNUMBER(SEARCH("Breakfast",$C16)),$D16="Asian"),RAND(),"") | H16: =IF(AND(ISNUMBER(SEARCH("Breakfast",$C16)),$D16="Chinese"),RAND(),"") | I16: =IF(AND(ISNUMBER(SEARCH("Breakfast",$C16)),$D16="Western"),RAND(),"") | J16: =IF(AND(ISNUMBER(SEARCH("Lunch",$C16)),$D16="Asian"),RAND(),"") | K16: =IF(AND(ISNUMBER(SEARCH("Lunch",$C16)),$D16="Chinese"),RAND(),"") | L16: =IF(AND(ISNUMBER(SEARCH("Lunch",$C16)),$D16="Western"),RAND(),"") | M16: =IF(AND(ISNUMBER(SEARCH("Dinner",$C16)),$D16="Asian"),RAND(),"") | N16: =IF(AND(ISNUMBER(SEARCH("Dinner",$C16)),$D16="Chinese"),RAND(),"") | O16: =IF(AND(ISNUMBER(SEARCH("Dinner",$C16)),$D16="Western"),RAND(),"")
A17: Bachormee Soup | B17: Egg Noodles, Meatballs, Minced Pork | C17: Lunch | D17: Western | E17: Med | G17: =IF(AND(ISNUMBER(SEARCH("Breakfast",$C17)),$D17="Asian"),RAND(),"") | H17: =IF(AND(ISNUMBER(SEARCH("Breakfast",$C17)),$D17="Chinese"),RAND(),"") | I17: =IF(AND(ISNUMBER(SEARCH("Breakfast",$C17)),$D17="Western"),RAND(),"") | J17: =IF(AND(ISNUMBER(SEARCH("Lunch",$C17)),$D17="Asian"),RAND(),"") | K17: =IF(AND(ISNUMBER(SEARCH("Lunch",$C17)),$D17="Chinese"),RAND(),"") | L17: =IF(AND(ISNUMBER(SEARCH("Lunch",$C17)),$D17="Western"),RAND(),"") | M17: =IF(AND(ISNUMBER(SEARCH("Dinner",$C17)),$D17="Asian"),RAND(),"") | N17: =IF(AND(ISNUMBER(SEARCH("Dinner",$C17)),$D17="Chinese"),RAND(),"") | O17: =IF(AND(ISNUMBER(SEARCH("Dinner",$C17)),$D17="Western"),RAND(),"") | P17: TRUE
A18: Back pain soup | B18: Pork Bone, 西施骨 | C18: Dinner | D18: Chinese | E18: Med | G18: =IF(AND(ISNUMBER(SEARCH("Breakfast",$C18)),$D18="Asian"),RAND(),"") | H18: =IF(AND(ISNUMBER(SEARCH("Breakfast",$C18)),$D18="Chinese"),RAND(),"") | I18: =IF(AND(ISNUMBER(SEARCH("Breakfast",$C18)),$D18="Western"),RAND(),"") | J18: =IF(AND(ISNUMBER(SEARCH("Lunch",$C18)),$D18="Asian"),RAND(),"") | K18: =IF(AND(ISNUMBER(SEARCH("Lunch",$C18)),$D18="Chinese"),RAND(),"") | L18: =IF(AND(ISNUMBER(SEARCH("Lunch",$C18)),$D18="Western"),RAND(),"") | M18: =IF(AND(ISNUMBER(SEARCH("Dinner",$C18)),$D18="Asian"),RAND(),"") | N18: =IF(AND(ISNUMBER(SEARCH("Dinner",$C18)),$D18="Chinese"),RAND(),"") | O18: =IF(AND(ISNUMBER(SEARCH("Dinner",$C18)),$D18="Western"),RAND(),"") | P18: TRUE
A19: Bacon | B19: Cabbage, Garlic | C19: Dinner | D19: Western | E19: Med | F19: https://icook.tw/recipes/166978?utm_source=copy&utm_medium=sharev3&utm_campaign=recipe-share | G19: =IF(AND(ISNUMBER(SEARCH("Breakfast",$C19)),$D19="Asian"),RAND(),"") | H19: =IF(AND(ISNUMBER(SEARCH("Breakfast",$C19)),$D19="Chinese"),RAND(),"") | I19: =IF(AND(ISNUMBER(SEARCH("Breakfast",$C19)),$D19="Western"),RAND(),"") | J19: =IF(AND(ISNUMBER(SEARCH("Lunch",$C19)),$D19="Asian"),RAND(),"") | K19: =IF(AND(ISNUMBER(SEARCH("Lunch",$C19)),$D19="Chinese"),RAND(),"") | L19: =IF(AND(ISNUMBER(SEARCH("Lunch",$C19)),$D19="Western"),RAND(),"") | M19: =IF(AND(ISNUMBER(SEARCH("Dinner",$C19)),$D19="Asian"),RAND(),"") | N19: =IF(AND(ISNUMBER(SEARCH("Dinner",$C19)),$D19="Chinese"),RAND(),"") | O19: =IF(AND(ISNUMBER(SEARCH("Dinner",$C19)),$D19="Western"),RAND(),"")
A20: Baicai | B20: Carrot, Enoki mushroom, Chilli | C20: Dinner | D20: Asian | E20: Low | F20: https://fb.watch/a9FI12brJ1/ | G20: =IF(AND(ISNUMBER(SEARCH("Breakfast",$C20)),$D20="Asian"),RAND(),"") | H20: =IF(AND(ISNUMBER(SEARCH("Breakfast",$C20)),$D20="Chinese"),RAND(),"") | I20: =IF(AND(ISNUMBER(SEARCH("Breakfast",$C20)),$D20="Western"),RAND(),"") | J20: =IF(AND(ISNUMBER(SEARCH("Lunch",$C20)),$D20="Asian"),RAND(),"") | K20: =IF(AND(ISNUMBER(SEARCH("Lunch",$C20)),$D20="Chinese"),RAND(),"") | L20: =IF(AND(ISNUMBER(SEARCH("Lunch",$C20)),$D20="Western"),RAND(),"") | M20: =IF(AND(ISNUMBER(SEARCH("Dinner",$C20)),$D20="Asian"),RAND(),"") | N20: =IF(AND(ISNUMBER(SEARCH("Dinner",$C20)),$D20="Chinese"),RAND(),"") | O20: =IF(AND(ISNUMBER(SEARCH("Dinner",$C20)),$D20="Western"),RAND(),"")
A21: Baimifen | B21: Prawns, Squid, Beehoon, Egg, Vege, Baimifen paste | C21: Lunch | D21: Chinese | E21: Med | G21: =IF(AND(ISNUMBER(SEARCH("Breakfast",$C21)),$D21="Asian"),RAND(),"") | H21: =IF(AND(ISNUMBER(SEARCH("Breakfast",$C21)),$D21="Chinese"),RAND(),"") | I21: =IF(AND(ISNUMBER(SEARCH("Breakfast",$C21)),$D21="Western"),RAND(),"") | J21: =IF(AND(ISNUMBER(SEARCH("Lunch",$C21)),$D21="Asian"),RAND(),"") | K21: =IF(AND(ISNUMBER(SEARCH("Lunch",$C21)),$D21="Chinese"),RAND(),"") | L21: =IF(AND(ISNUMBER(SEARCH("Lunch",$C21)),$D21="Western"),RAND(),"") | M21: =IF(AND(ISNUMBER(SEARCH("Dinner",$C21)),$D21="Asian"),RAND(),"") | N21: =IF(AND(ISNUMBER(SEARCH("Dinner",$C21)),$D21="Chinese"),RAND(),"") | O21: =IF(AND(ISNUMBER(SEARCH("Dinner",$C21)),$D21="Western"),RAND(),"")
A22: Bak Kut Teh | B22: 排骨, BKT Herbs | C22: Dinner | D22: Chinese | E22: High | G22: =IF(AND(ISNUMBER(SEARCH("Breakfast",$C22)),$D22="Asian"),RAND(),"") | H22: =IF(AND(ISNUMBER(SEARCH("Breakfast",$C22)),$D22="Chinese"),RAND(),"") | I22: =IF(AND(ISNUMBER(SEARCH("Breakfast",$C22)),$D22="Western"),RAND(),"") | J22: =IF(AND(ISNUMBER(SEARCH("Lunch",$C22)),$D22="Asian"),RAND(),"") | K22: =IF(AND(ISNUMBER(SEARCH("Lunch",$C22)),$D22="Chinese"),RAND(),"") | L22: =IF(AND(ISNUMBER(SEARCH("Lunch",$C22)),$D22="Western"),RAND(),"") | M22: =IF(AND(ISNUMBER(SEARCH("Dinner",$C22)),$D22="Asian"),RAND(),"") | N22: =IF(AND(ISNUMBER(SEARCH("Dinner",$C22)),$D22="Chinese"),RAND(),"") | O22: =IF(AND(ISNUMBER(SEARCH("Dinner",$C22)),$D22="Western"),RAND(),"")
A23: Baked Carrot Fries | B23: Carrot, Parmesan, Oregano, Garlic Powder, Paprika, Mayonaise, Chilli Sauce, Parsley | C23: Dinner | D23: Western | E23: High | F23: https://youtu.be/ZD_5nZr9yhM | G23: =IF(AND(ISNUMBER(SEARCH("Breakfast",$C23)),$D23="Asian"),RAND(),"") | H23: =IF(AND(ISNUMBER(SEARCH("Breakfast",$C23)),$D23="Chinese"),RAND(),"") | I23: =IF(AND(ISNUMBER(SEARCH("Breakfast",$C23)),$D23="Western"),RAND(),"") | J23: =IF(AND(ISNUMBER(SEARCH("Lunch",$C23)),$D23="Asian"),RAND(),"") | K23: =IF(AND(ISNUMBER(SEARCH("Lunch",$C23)),$D23="Chinese"),RAND(),"") | L23: =IF(AND(ISNUMBER(SEARCH("Lunch",$C23)),$D23="Western"),RAND(),"") | M23: =IF(AND(ISNUMBER(SEARCH("Dinner",$C23)),$D23="Asian"),RAND(),"") | N23: =IF(AND(ISNUMBER(SEARCH("Dinner",$C23)),$D23="Chinese"),RAND(),"") | O23: =IF(AND(ISNUMBER(SEARCH("Dinner",$C23)),$D23="Western"),RAND(),"")
A24: Baked chicken Italian | B24: Chicken breast, Oregano, Thyme, Paprika, Garlic, Lemon, Red onion, tomato, Parsley, Basil | C24: Dinner | D24: Western | E24: Low | F24: https://youtu.be/jYkqDKxsdxE | G24: =IF(AND(ISNUMBER(SEARCH("Breakfast",$C24)),$D24="Asian"),RAND(),"") | H24: =IF(AND(ISNUMBER(SEARCH("Breakfast",$C24)),$D24="Chinese"),RAND(),"") | I24: =IF(AND(ISNUMBER(SEARCH("Breakfast",$C24)),$D24="Western"),RAND(),"") | J24: =IF(AND(ISNUMBER(SEARCH("Lunch",$C24)),$D24="Asian"),RAND(),"") | K24: =IF(AND(ISNUMBER(SEARCH("Lunch",$C24)),$D24="Chinese"),RAND(),"") | L24: =IF(AND(ISNUMBER(SEARCH("Lunch",$C24)),$D24="Western"),RAND(),"") | M24: =IF(AND(ISNUMBER(SEARCH("Dinner",$C24)),$D24="Asian"),RAND(),"") | N24: =IF(AND(ISNUMBER(SEARCH("Dinner",$C24)),$D24="Chinese"),RAND(),"") | O24: =IF(AND(ISNUMBER(SEARCH("Dinner",$C24)),$D24="Western"),RAND(),"")
A25: Baked Halibut | B25: Mayonaise, Shallot, Lemon Juice, Cilantro, Chives, Dijon Mustard, Halibut | C25: Dinner | D25: Western | E25: Med | G25: =IF(AND(ISNUMBER(SEARCH("Breakfast",$C25)),$D25="Asian"),RAND(),"") | H25: =IF(AND(ISNUMBER(SEARCH("Breakfast",$C25)),$D25="Chinese"),RAND(),"") | I25: =IF(AND(ISNUMBER(SEARCH("Breakfast",$C25)),$D25="Western"),RAND(),"") | J25: =IF(AND(ISNUMBER(SEARCH("Lunch",$C25)),$D25="Asian"),RAND(),"") | K25: =IF(AND(ISNUMBER(SEARCH("Lunch",$C25)),$D25="Chinese"),RAND(),"") | L25: =IF(AND(ISNUMBER(SEARCH("Lunch",$C25)),$D25="Western"),RAND(),"") | M25: =IF(AND(ISNUMBER(SEARCH("Dinner",$C25)),$D25="Asian"),RAND(),"") | N25: =IF(AND(ISNUMBER(SEARCH("Dinner",$C25)),$D25="Chinese"),RAND(),"") | O25: =IF(AND(ISNUMBER(SEARCH("Dinner",$C25)),$D25="Western"),RAND(),"")
A26: Baked macaroni | B26: Eggs, Nutmeg powder, Black pepper, Ground pork with onions, Macaroni, Cheddar cheese, Milk, Cream cheese | C26: Dinner | D26: Western | E26: Med | F26: https://www.instagram.com/reel/DCk9dYUAOQl/?igsh=d3UwcXdqZnl3bnR0 | G26: =IF(AND(ISNUMBER(SEARCH("Breakfast",$C26)),$D26="Asian"),RAND(),"") | H26: =IF(AND(ISNUMBER(SEARCH("Breakfast",$C26)),$D26="Chinese"),RAND(),"") | I26: =IF(AND(ISNUMBER(SEARCH("Breakfast",$C26)),$D26="Western"),RAND(),"") | J26: =IF(AND(ISNUMBER(SEARCH("Lunch",$C26)),$D26="Asian"),RAND(),"") | K26: =IF(AND(ISNUMBER(SEARCH("Lunch",$C26)),$D26="Chinese"),RAND(),"") | L26: =IF(AND(ISNUMBER(SEARCH("Lunch",$C26)),$D26="Western"),RAND(),"") | M26: =IF(AND(ISNUMBER(SEARCH("Dinner",$C26)),$D26="Asian"),RAND(),"") | N26: =IF(AND(ISNUMBER(SEARCH("Dinner",$C26)),$D26="Chinese"),RAND(),"") | O26: =IF(AND(ISNUMBER(SEARCH("Dinner",$C26)),$D26="Western"),RAND(),"")
A27: Baked potato with beans | B27: Potato, Baked beans, Canned sweet corn, Garlic, Cumin, Sour cream, Green onion, Cheese | C27: Dinner | D27: Western | E27: Med | F27: https://www.kitchenstories.com/en/recipes/baked-potatoes-with-corn-and-beans | G27: =IF(AND(ISNUMBER(SEARCH("Breakfast",$C27)),$D27="Asian"),RAND(),"") | H27: =IF(AND(ISNUMBER(SEARCH("Breakfast",$C27)),$D27="Chinese"),RAND(),"") | I27: =IF(AND(ISNUMBER(SEARCH("Breakfast",$C27)),$D27="Western"),RAND(),"") | J27: =IF(AND(ISNUMBER(SEARCH("Lunch",$C27)),$D27="Asian"),RAND(),"") | K27: =IF(AND(ISNUMBER(SEARCH("Lunch",$C27)),$D27="Chinese"),RAND(),"") | L27: =IF(AND(ISNUMBER(SEARCH("Lunch",$C27)),$D27="Western"),RAND(),"") | M27: =IF(AND(ISNUMBER(SEARCH("Dinner",$C27)),$D27="Asian"),RAND(),"") | N27: =IF(AND(ISNUMBER(SEARCH("Dinner",$C27)),$D27="Chinese"),RAND(),"") | O27: =IF(AND(ISNUMBER(SEARCH("Dinner",$C27)),$D27="Western"),RAND(),"")
A28: Baked Salmon | B28: Salmon, Nectarines, Lemon, Granny smith apples, cucumber, can sweet corn, rosemary | C28: Dinner | D28: Western | E28: Low | F28: https://www.kitchenstories.com/en/recipes/baked-salmon-with-nectarine-salsa | G28: =IF(AND(ISNUMBER(SEARCH("Breakfast",$C28)),$D28="Asian"),RAND(),"") | H28: =IF(AND(ISNUMBER(SEARCH("Breakfast",$C28)),$D28="Chinese"),RAND(),"") | I28: =IF(AND(ISNUMBER(SEARCH("Breakfast",$C28)),$D28="Western"),RAND(),"") | J28: =IF(AND(ISNUMBER(SEARCH("Lunch",$C28)),$D28="Asian"),RAND(),"") | K28: =IF(AND(ISNUMBER(SEARCH("Lunch",$C28)),$D28="Chinese"),RAND(),"") | L28: =IF(AND(ISNUMBER(SEARCH("Lunch",$C28)),$D28="Western"),RAND(),"") | M28: =IF(AND(ISNUMBER(SEARCH("Dinner",$C28)),$D28="Asian"),RAND(),"") | N28: =IF(AND(ISNUMBER(SEARCH("Dinner",$C28)),$D28="Chinese"),RAND(),"") | O28: =IF(AND(ISNUMBER(SEARCH("Dinner",$C28)),$D28="Western"),RAND(),"")
A29: Banana cake | B29: All purpose flour, Baking soda, unsalted butter, sugar, vanilla, milk, banana, chocolate chunks | C29: Breakfast | D29: Western | E29: Med | F29: https://makeitdough.com/sourdough-discard-banana-snack-cake/ | G29: =IF(AND(ISNUMBER(SEARCH("Breakfast",$C29)),$D29="Asian"),RAND(),"") | H29: =IF(AND(ISNUMBER(SEARCH("Breakfast",$C29)),$D29="Chinese"),RAND(),"") | I29: =IF(AND(ISNUMBER(SEARCH("Breakfast",$C29)),$D29="Western"),RAND(),"") | J29: =IF(AND(ISNUMBER(SEARCH("Lunch",$C29)),$D29="Asian"),RAND(),"") | K29: =IF(AND(ISNUMBER(SEARCH("Lunch",$C29)),$D29="Chinese"),RAND(),"") | L29: =IF(AND(ISNUMBER(SEARCH("Lunch",$C29)),$D29="Western"),RAND(),"") | M29: =IF(AND(ISNUMBER(SEARCH("Dinner",$C29)),$D29="Asian"),RAND(),"") | N29: =IF(AND(ISNUMBER(SEARCH("Dinner",$C29)),$D29="Chinese"),RAND(),"") | O29: =IF(AND(ISNUMBER(SEARCH("Dinner",$C29)),$D29="Western"),RAND(),"")
